<?xml version="1.0" ?>
<!-- =================================================================================== -->
<!-- |    This document was autogenerated by xacro from jaws2.urdf.xacro               | -->
<!-- |    EDITING THIS FILE BY HAND IS NOT RECOMMENDED                                 | -->
<!-- =================================================================================== -->
<robot name="jaws2" xmlns:xacro="http://ros.org/wiki/xacro">
  <!-- Servo Interface -->
  <transmission name="port">
    <type>transmission_interface/SimpleTransmission</type>
    <joint name="port_servo">
      <hardwareInterface>EffortJointInterface</hardwareInterface>
    </joint>
    <actuator name="port_servo_motor">
      <hardwareInterface>EffortJointInterface</hardwareInterface>
      <mechanicalReduction>1</mechanicalReduction>
    </actuator>
  </transmission>
  <transmission name="stbd">
    <type>transmission_interface/SimpleTransmission</type>
    <joint name="stbd_servo">
      <hardwareInterface>EffortJointInterface</hardwareInterface>
    </joint>
    <actuator name="stbd_servo_motor">
      <hardwareInterface>EffortJointInterface</hardwareInterface>
      <mechanicalReduction>1</mechanicalReduction>
    </actuator>
  </transmission>
  <!--  Dummy Link  -->
  <link name="base_link"/>
  <joint name="housing" type="fixed">
    <parent link="base_link"/>
    <child link="housing"/>
  </joint>
  <!--  Main Housing Inertia  -->
  <link name="housing">
    <inertial>
      <mass value="1.8914"/>
      <inertia ixx="0.00921641" ixy="0.0" ixz="0.0" iyy="0.03285281" iyz="0.0" izz="0.03285281"/>
    </inertial>
  </link>
  <!--  Main Housing Volume  -->
  <joint name="fwd_housing_joint" type="fixed">
    <origin rpy="0 0 0" xyz="0.1659 0 0"/>
    <parent link="mid_housing"/>
    <child link="fwd_housing"/>
  </joint>
  <joint name="mid_housing_joint" type="fixed">
    <origin rpy="0 0 0" xyz="-0.0127 0 0"/>
    <parent link="housing"/>
    <child link="mid_housing"/>
  </joint>
  <joint name="aft_housing_joint" type="fixed">
    <origin rpy="0 0 0" xyz="-0.1532 0 0"/>
    <parent link="mid_housing"/>
    <child link="aft_housing"/>
  </joint>
  <link name="fwd_housing">
    <visual>
      <origin rpy="0 1.57079633 0" xyz="0 0 0"/>
      <geometry>
        <cylinder length="0.0492" radius="0.0762"/>
      </geometry>
      <material name="FlatBlack"/>
    </visual>
    <collision>
      <origin rpy="0 1.57079633 0" xyz="0 0 0"/>
      <geometry>
        <cylinder length="0.0492" radius="0.0762"/>
      </geometry>
    </collision>
  </link>
  <link name="mid_housing">
    <visual>
      <origin rpy="0 1.57079633 0" xyz="0 0 0"/>
      <geometry>
        <cylinder length="0.2826" radius="0.06985"/>
      </geometry>
      <material name="FlatBlack"/>
    </visual>
    <collision>
      <origin rpy="0 1.57079633 0" xyz="0 0 0"/>
      <geometry>
        <cylinder length="0.2826" radius="0.06985"/>
      </geometry>
    </collision>
  </link>
  <link name="aft_housing">
    <visual>
      <origin rpy="0 1.57079633 0" xyz="0 0 0"/>
      <geometry>
        <cylinder length="0.0238" radius="0.0762"/>
      </geometry>
      <material name="FlatBlack"/>
    </visual>
    <collision>
      <origin rpy="0 1.57079633 0" xyz="0 0 0"/>
      <geometry>
        <cylinder length="0.0238" radius="0.0762"/>
      </geometry>
    </collision>
  </link>
  <!--  Gaskets  -->
  <joint name="fwd_gasket_joint" type="fixed">
    <origin rpy="0 0 0" xyz="0.1794 0 0"/>
    <parent link="housing"/>
    <child link="fwd_gasket"/>
  </joint>
  <link name="fwd_gasket">
    <inertial>
      <mass value="0.0165"/>
      <inertia ixx="0.00004790" ixy="0.0" ixz="0.0" iyy="0.00002397" iyz="0.0" izz="0.00002397"/>
    </inertial>
    <visual>
      <origin rpy="0 1.57079633 0" xyz="0 0 0"/>
      <geometry>
        <cylinder length="0.0032" radius="0.0762"/>
      </geometry>
      <material name="Orange"/>
    </visual>
    <collision>
      <origin rpy="0 1.57079633 0" xyz="0 0 0"/>
      <geometry>
        <cylinder length="0.0032" radius="0.0762"/>
      </geometry>
    </collision>
  </link>
  <joint name="aft_gasket_joint" type="fixed">
    <origin rpy="0 0 0" xyz="-0.1794 0 0"/>
    <parent link="housing"/>
    <child link="aft_gasket"/>
  </joint>
  <link name="aft_gasket">
    <inertial>
      <mass value="0.0165"/>
      <inertia ixx="0.00004790" ixy="0.0" ixz="0.0" iyy="0.00002397" iyz="0.0" izz="0.00002397"/>
    </inertial>
    <visual>
      <origin rpy="0 1.57079633 0" xyz="0 0 0"/>
      <geometry>
        <cylinder length="0.0032" radius="0.0762"/>
      </geometry>
      <material name="Orange"/>
    </visual>
    <collision>
      <origin rpy="0 1.57079633 0" xyz="0 0 0"/>
      <geometry>
        <cylinder length="0.0032" radius="0.0762"/>
      </geometry>
    </collision>
  </link>
  <!--  Dome/Endcap  -->
  <joint name="dome_joint" type="fixed">
    <origin rpy="0 0 0" xyz="0.0016 0 0"/>
    <parent link="fwd_gasket"/>
    <child link="dome"/>
  </joint>
  <joint name="endcap_joint" type="fixed">
    <origin rpy="0 0 0" xyz="-0.0116 0 0"/>
    <parent link="aft_gasket"/>
    <child link="endcap"/>
  </joint>
  <link name="dome">
    <inertial>
      <mass value="0.77"/>
      <inertia ixx="0.003" ixy="0.0" ixz="0.0" iyy="0.003" iyz="0.0" izz="0.003"/>
    </inertial>
    <visual>
      <geometry>
        <sphere radius="0.0762"/>
        <!-- <mesh filename="package://jaws2_description/meshes/dome.stl" /> -->
      </geometry>
      <material name="Grey"/>
    </visual>
    <collision>
      <geometry>
        <sphere radius="0.0762"/>
      </geometry>
    </collision>
  </link>
  <link name="endcap">
    <inertial>
      <mass value="0.1925"/>
      <inertia ixx="0.000" ixy="0.0" ixz="0.0" iyy="0.003" iyz="0.0" izz="0.003"/>
    </inertial>
    <visual>
      <origin rpy="0 1.57079633 0" xyz="0 0 0"/>
      <geometry>
        <cylinder length="0.02" radius="0.0762"/>
      </geometry>
      <material name="Grey"/>
    </visual>
    <collision>
      <origin rpy="0 1.57079633 0" xyz="0 0 0"/>
      <geometry>
        <cylinder length="0.02" radius="0.0762"/>
      </geometry>
    </collision>
  </link>
  <!--  Port & Starboard Servos  -->
  <joint name="port_servo" type="revolute">
    <origin rpy="0 -1.57079633 0" xyz="0.142875 0.09763125 0"/>
    <parent link="housing"/>
    <child link="port_servo_shaft"/>
    <axis xyz="0 1 0"/>
    <limit effort="1.4994" lower="-2.09439510667" upper="2.09439510667" velocity="1.9666"/>
  </joint>
  <link name="port_servo_shaft">
    <inertial>
      <mass value="0.02320847"/>
      <inertia ixx="0.00000444" ixy="0.0" ixz="0.0" iyy="0.00000506" iyz="0.0" izz="0.00000444"/>
    </inertial>
    <visual>
      <origin rpy="1.57079633 0 0" xyz="0 0 0"/>
      <geometry>
        <cylinder length="0.0238125" radius="0.01580619"/>
      </geometry>
      <material name="DarkGrey"/>
    </visual>
    <collision>
      <origin rpy="1.57079633 0 0" xyz="0 0 0"/>
      <geometry>
        <cylinder length="0.0238125" radius="0.01580619"/>
      </geometry>
    </collision>
  </link>
  <joint name="stbd_servo" type="revolute">
    <origin rpy="0 -1.57079633 3.14159266" xyz="0.142875 -0.09763125 0"/>
    <parent link="housing"/>
    <child link="stbd_servo_shaft"/>
    <axis xyz="0 1 0"/>
    <limit effort="1.4994" lower="-2.09439510667" upper="2.09439510667" velocity="1.9666"/>
  </joint>
  <link name="stbd_servo_shaft">
    <inertial>
      <mass value="0.02320847"/>
      <inertia ixx="0.00000444" ixy="0.0" ixz="0.0" iyy="0.00000506" iyz="0.0" izz="0.00000444"/>
    </inertial>
    <visual>
      <origin rpy="1.57079633 0 0" xyz="0 0 0"/>
      <geometry>
        <cylinder length="0.0238125" radius="0.01580619"/>
      </geometry>
      <material name="DarkGrey"/>
    </visual>
    <collision>
      <origin rpy="1.57079633 0 0" xyz="0 0 0"/>
      <geometry>
        <cylinder length="0.0238125" radius="0.01580619"/>
      </geometry>
    </collision>
  </link>
  <!--  Aft Thruster Riser  -->
  <joint name="aft_thruster_riser_joint" type="fixed">
    <origin rpy="0 0 0" xyz="-0.1397 0 0.0841375"/>
    <parent link="housing"/>
    <child link="aft_thruster_riser"/>
  </joint>
  <link name="aft_thruster_riser">
    <inertial>
      <mass value="0.02320847"/>
      <inertia ixx="0.00000162" ixy="0.0" ixz="0.0" iyy="0.00000162" iyz="0.0" izz="0.00000262"/>
    </inertial>
    <visual>
      <geometry>
        <box size="0.0195 0.0143 0.0127"/>
      </geometry>
      <material name="DarkGrey"/>
    </visual>
    <collision>
      <geometry>
        <box size="0.026 0.026 0.0127"/>
      </geometry>
    </collision>
  </link>
  <!--  Port & Stbd Shaft Seals  -->
  <joint name="port_thruster_mount_joint" type="fixed">
    <origin rpy="0 0 0" xyz="0.142875 0.07381875 0"/>
    <parent link="housing"/>
    <child link="port_thruster_mount"/>
  </joint>
  <link name="port_thruster_mount">
    <visual>
      <origin rpy="1.57079633 0 0" xyz="0 0 0"/>
      <geometry>
        <cylinder length="0.0238125" radius="0.0118546425"/>
      </geometry>
      <material name="FlatBlack"/>
    </visual>
  </link>
  <joint name="stbd_thruster_mount_joint" type="fixed">
    <origin rpy="0 0 0" xyz="0.142875 -0.07381875 0"/>
    <parent link="housing"/>
    <child link="stbd_thruster_mount"/>
  </joint>
  <link name="stbd_thruster_mount">
    <visual>
      <origin rpy="1.57079633 0 0" xyz="0 0 0"/>
      <geometry>
        <cylinder length="0.0238125" radius="0.0118546425"/>
      </geometry>
      <material name="FlatBlack"/>
    </visual>
  </link>
  <!--  Aft Thruster Mounting Point  -->
  <joint name="aft_thruster_mount_joint" type="fixed">
    <origin rpy="0 0 0" xyz="-0.1397 0 0.0714375"/>
    <parent link="housing"/>
    <child link="aft_thruster_mount"/>
  </joint>
  <link name="aft_thruster_mount">
    <visual>
      <geometry>
        <cylinder length="0.0127" radius="0.013"/>
      </geometry>
      <material name="FlatBlack"/>
    </visual>
  </link>
  <!--  Housing Properties  -->
  <!-- Gasket Properties  -->
  <!--  Dome Properties  -->
  <!--  Endcap Properties  -->
  <!--  Port & Stbd Servo Propeties  -->
  <!--  Aft Thruster Riser Properties  -->
  <!--  Miscellaneous  -->
  <!--  Rviz Materials  -->
  <material name="FlatBlack">
    <color rgba="0.1 0.1 0.1 1.0"/>
  </material>
  <material name="DarkGrey">
    <color rgba="0.175 0.175 0.175 1.0"/>
  </material>
  <material name="Grey">
    <color rgba="0.3 0.3 0.3 1.0"/>
  </material>
  <material name="GreyTransparent">
    <color rgba="0.5 0.5 0.5 0.5"/>
  </material>
  <material name="Orange">
    <color rgba="1 0.5088 0.0468 1"/>
  </material>
  <gazebo>
    <!--  Buoyancy  -->
    <plugin filename="libBuoyancyPlugin.so" name="BuoyancyPlugin"/>
    <!--  Servo Simulation Interface  -->
    <plugin filename="libgazebo_ros_control.so" name="gazebo_ros_control">
      <robotNamespace>/jaws2</robotNamespace>
    </plugin>
    <!--  Thruster Simulation Interface  -->
    <plugin filename="libgazebo_ros_force.so" name="gazebo_ros_force">
      <bodyName>aft_thruster</bodyName>
      <topicName>aft_thrust</topicName>
    </plugin>
    <plugin filename="libgazebo_ros_force.so" name="gazebo_ros_force">
      <bodyName>port_thruster</bodyName>
      <topicName>port_thrust</topicName>
    </plugin>
    <plugin filename="libgazebo_ros_force.so" name="gazebo_ros_force">
      <bodyName>stbd_thruster</bodyName>
      <topicName>stbd_thrust</topicName>
    </plugin>
  </gazebo>
  <!--  Gazebo Materials  -->
  <gazebo reference="dome">
    <material>Gazebo/Grey</material>
  </gazebo>
  <gazebo reference="mid_housing">
    <material>Gazebo/FlatBlack</material>
  </gazebo>
  <gazebo reference="endcap">
    <material>Gazebo/Grey</material>
  </gazebo>
  <gazebo reference="aft_thruster_mount">
    <material>Gazebo/FlatBlack</material>
  </gazebo>
  <gazebo reference="aft_thruster_riser">
    <material>Gazebo/DarkGrey</material>
  </gazebo>
  <gazebo reference="fwd_housing">
    <material>Gazebo/FlatBlack</material>
  </gazebo>
  <gazebo reference="fwd_gasket">
    <material>Gazebo/Orange</material>
  </gazebo>
  <gazebo reference="port_thruster_mount">
    <material>Gazebo/FlatBlack</material>
  </gazebo>
  <gazebo reference="port_servo_shaft">
    <material>Gazebo/DarkGrey</material>
  </gazebo>
  <gazebo reference="aft_housing">
    <material>Gazebo/FlatBlack</material>
  </gazebo>
  <gazebo reference="aft_gasket">
    <material>Gazebo/Orange</material>
  </gazebo>
  <gazebo reference="stbd_thruster_mount">
    <material>Gazebo/FlatBlack</material>
  </gazebo>
  <gazebo reference="stbd_servo_shaft">
    <material>Gazebo/DarkGrey</material>
  </gazebo>
  <!-- http://www.seabotix.com/products/pdf_files/BTD150_Data_Sheet.pdf -->
  <gazebo reference="port_thruster">
    <material>Gazebo/Grey</material>
  </gazebo>
  <gazebo reference="port_thruster_nose_cone">
    <material>Gazebo/DarkGrey</material>
  </gazebo>
  <gazebo reference="port_thruster_nozzle">
    <material>Gazebo/DarkGrey</material>
  </gazebo>
  <gazebo reference="stbd_thruster">
    <material>Gazebo/Grey</material>
  </gazebo>
  <gazebo reference="stbd_thruster_nose_cone">
    <material>Gazebo/DarkGrey</material>
  </gazebo>
  <gazebo reference="stbd_thruster_nozzle">
    <material>Gazebo/DarkGrey</material>
  </gazebo>
  <gazebo reference="aft_thruster">
    <material>Gazebo/Grey</material>
  </gazebo>
  <gazebo reference="aft_thruster_nose_cone">
    <material>Gazebo/DarkGrey</material>
  </gazebo>
  <gazebo reference="aft_thruster_nozzle">
    <material>Gazebo/DarkGrey</material>
  </gazebo>
  <!-- Build the Thrusters -->
  <link name="port_thruster">
    <inertial>
      <mass value="0.709"/>
      <inertia ixx="0.00017511" ixy="0.0000" ixz="0.0000" iyy="0.00191980" iyz="0.0000" izz="0.00191980"/>
    </inertial>
    <visual>
      <origin rpy="0 1.57079633 0" xyz="0 0 0"/>
      <geometry>
        <cylinder length="0.13165" radius="0.022225"/>
      </geometry>
      <material name="Grey"/>
    </visual>
    <collision>
      <origin rpy="0 1.57079633 0" xyz="0 0 0"/>
      <geometry>
        <cylinder length="0.1761" radius="0.022225"/>
      </geometry>
    </collision>
  </link>
  <link name="port_thruster_nose_cone">
    <visual>
      <geometry>
        <sphere radius="0.022225"/>
      </geometry>
      <material name="DarkGrey"/>
    </visual>
  </link>
  <link name="port_thruster_nozzle">
    <visual>
      <origin rpy="0 1.57079633 0" xyz="0 0 0"/>
      <geometry>
        <cylinder length="0.0503" radius="0.0474"/>
      </geometry>
      <material name="DarkGrey"/>
    </visual>
  </link>
  <joint name="port_thruster_nose_cone" type="fixed">
    <origin rpy="0 0 0" xyz="0.065825 0 0"/>
    <parent link="port_thruster"/>
    <child link="port_thruster_nose_cone"/>
  </joint>
  <joint name="port_thruster_nozzle" type="fixed">
    <origin rpy="0 0 0" xyz="-0.0629 0 0"/>
    <parent link="port_thruster"/>
    <child link="port_thruster_nozzle"/>
  </joint>
  <link name="stbd_thruster">
    <inertial>
      <mass value="0.709"/>
      <inertia ixx="0.00017511" ixy="0.0000" ixz="0.0000" iyy="0.00191980" iyz="0.0000" izz="0.00191980"/>
    </inertial>
    <visual>
      <origin rpy="0 1.57079633 0" xyz="0 0 0"/>
      <geometry>
        <cylinder length="0.13165" radius="0.022225"/>
      </geometry>
      <material name="Grey"/>
    </visual>
    <collision>
      <origin rpy="0 1.57079633 0" xyz="0 0 0"/>
      <geometry>
        <cylinder length="0.1761" radius="0.022225"/>
      </geometry>
    </collision>
  </link>
  <link name="stbd_thruster_nose_cone">
    <visual>
      <geometry>
        <sphere radius="0.022225"/>
      </geometry>
      <material name="DarkGrey"/>
    </visual>
  </link>
  <link name="stbd_thruster_nozzle">
    <visual>
      <origin rpy="0 1.57079633 0" xyz="0 0 0"/>
      <geometry>
        <cylinder length="0.0503" radius="0.0474"/>
      </geometry>
      <material name="DarkGrey"/>
    </visual>
  </link>
  <joint name="stbd_thruster_nose_cone" type="fixed">
    <origin rpy="0 0 0" xyz="0.065825 0 0"/>
    <parent link="stbd_thruster"/>
    <child link="stbd_thruster_nose_cone"/>
  </joint>
  <joint name="stbd_thruster_nozzle" type="fixed">
    <origin rpy="0 0 0" xyz="-0.0629 0 0"/>
    <parent link="stbd_thruster"/>
    <child link="stbd_thruster_nozzle"/>
  </joint>
  <link name="aft_thruster">
    <inertial>
      <mass value="0.709"/>
      <inertia ixx="0.00017511" ixy="0.0000" ixz="0.0000" iyy="0.00191980" iyz="0.0000" izz="0.00191980"/>
    </inertial>
    <visual>
      <origin rpy="0 1.57079633 0" xyz="0 0 0"/>
      <geometry>
        <cylinder length="0.13165" radius="0.022225"/>
      </geometry>
      <material name="Grey"/>
    </visual>
    <collision>
      <origin rpy="0 1.57079633 0" xyz="0 0 0"/>
      <geometry>
        <cylinder length="0.1761" radius="0.022225"/>
      </geometry>
    </collision>
  </link>
  <link name="aft_thruster_nose_cone">
    <visual>
      <geometry>
        <sphere radius="0.022225"/>
      </geometry>
      <material name="DarkGrey"/>
    </visual>
  </link>
  <link name="aft_thruster_nozzle">
    <visual>
      <origin rpy="0 1.57079633 0" xyz="0 0 0"/>
      <geometry>
        <cylinder length="0.0503" radius="0.0474"/>
      </geometry>
      <material name="DarkGrey"/>
    </visual>
  </link>
  <joint name="aft_thruster_nose_cone" type="fixed">
    <origin rpy="0 0 0" xyz="0.065825 0 0"/>
    <parent link="aft_thruster"/>
    <child link="aft_thruster_nose_cone"/>
  </joint>
  <joint name="aft_thruster_nozzle" type="fixed">
    <origin rpy="0 0 0" xyz="-0.0629 0 0"/>
    <parent link="aft_thruster"/>
    <child link="aft_thruster_nozzle"/>
  </joint>
  <!-- Attach the Thrusters -->
  <joint name="port_thruster_joint" type="fixed">
    <origin rpy="0 0 0" xyz="0 0.03413125 0"/>
    <parent link="port_servo_shaft"/>
    <child link="port_thruster"/>
  </joint>
  <joint name="stbd_thruster_joint" type="fixed">
    <origin rpy="0 0 0" xyz="0 0.03413125 0"/>
    <parent link="stbd_servo_shaft"/>
    <child link="stbd_thruster"/>
  </joint>
  <joint name="aft_thruster_joint" type="fixed">
    <origin rpy="0 0 0" xyz="-0.0293125 0 0.028575"/>
    <parent link="aft_thruster_riser"/>
    <child link="aft_thruster"/>
  </joint>
</robot>

